<Type Name="TargetInvocationException" FullName="System.Reflection.TargetInvocationException">
  <Metadata><Meta Name="ms.openlocfilehash" Value="5891576538defa830d2c6d023736d390d5ae148d" /><Meta Name="ms.sourcegitcommit" Value="8ae9a18b248625c8e1851e607c00346a64849587" /><Meta Name="ms.translationtype" Value="MT" /><Meta Name="ms.contentlocale" Value="ja-JP" /><Meta Name="ms.lasthandoff" Value="12/17/2019" /><Meta Name="ms.locfileid" Value="75166994" /></Metadata><TypeSignature Language="C#" Value="public sealed class TargetInvocationException : ApplicationException" />
  <TypeSignature Language="ILAsm" Value=".class public auto ansi serializable sealed beforefieldinit TargetInvocationException extends System.ApplicationException" />
  <TypeSignature Language="DocId" Value="T:System.Reflection.TargetInvocationException" />
  <TypeSignature Language="VB.NET" Value="Public NotInheritable Class TargetInvocationException&#xA;Inherits ApplicationException" />
  <TypeSignature Language="C++ CLI" Value="public ref class TargetInvocationException sealed : ApplicationException" />
  <TypeSignature Language="F#" Value="type TargetInvocationException = class&#xA;    inherit ApplicationException" />
  <AssemblyInfo>
    <AssemblyName>System.Reflection</AssemblyName>
    <AssemblyVersion>4.0.0.0</AssemblyVersion>
    <AssemblyVersion>4.0.10.0</AssemblyVersion>
    <AssemblyVersion>4.1.0.0</AssemblyVersion>
  </AssemblyInfo>
  <AssemblyInfo>
    <AssemblyName>mscorlib</AssemblyName>
    <AssemblyVersion>1.0.5000.0</AssemblyVersion>
    <AssemblyVersion>2.0.0.0</AssemblyVersion>
    <AssemblyVersion>2.0.5.0</AssemblyVersion>
    <AssemblyVersion>4.0.0.0</AssemblyVersion>
  </AssemblyInfo>
  <AssemblyInfo>
    <AssemblyName>netstandard</AssemblyName>
    <AssemblyVersion>2.0.0.0</AssemblyVersion>
    <AssemblyVersion>2.1.0.0</AssemblyVersion>
  </AssemblyInfo>
  <AssemblyInfo>
    <AssemblyName>System.Runtime</AssemblyName>
    <AssemblyVersion>4.2.0.0</AssemblyVersion>
    <AssemblyVersion>4.2.1.0</AssemblyVersion>
    <AssemblyVersion>4.2.2.0</AssemblyVersion>
  </AssemblyInfo>
  <Base>
    <BaseTypeName>System.Exception</BaseTypeName>
    <BaseTypeName FrameworkAlternate="netframework-4.5">System.ApplicationException</BaseTypeName>
  </Base>
  <Interfaces />
  <Attributes>
    <Attribute FrameworkAlternate="netframework-2.0;netframework-3.0;netframework-3.5;netframework-4.0;netframework-4.5;netframework-4.5.1;netframework-4.5.2;netframework-4.6;netframework-4.6.1;netframework-4.6.2;netframework-4.7;netframework-4.7.1;netframework-4.7.2;xamarinandroid-7.1;xamarinios-10.8;xamarinmac-3.0;netframework-4.8">
      <AttributeName>System.Runtime.InteropServices.ComVisible(true)</AttributeName>
    </Attribute>
    <Attribute FrameworkAlternate="netframework-1.1;netframework-2.0;netframework-3.0;netframework-3.5;netframework-4.0;netframework-4.5;netframework-4.5.1;netframework-4.5.2;netframework-4.6;netframework-4.6.1;netframework-4.6.2;netframework-4.7;netframework-4.7.1;netframework-4.7.2;netframework-4.8;xamarinandroid-7.1;xamarinios-10.8;xamarinmac-3.0">
      <AttributeName>System.Serializable</AttributeName>
    </Attribute>
  </Attributes>
  <Docs>
    <summary><span data-ttu-id="11414-101">リフレクションを通じて呼び出されたメソッドがスローする例外。</span><span class="sxs-lookup"><span data-stu-id="11414-101">The exception that is thrown by methods invoked through reflection.</span></span> <span data-ttu-id="11414-102">このクラスは継承できません。</span><span class="sxs-lookup"><span data-stu-id="11414-102">This class cannot be inherited.</span></span></summary>
    <remarks>
      <format type="text/markdown"><![CDATA[  
  
## Remarks  
 <span data-ttu-id="11414-103">詳細については、「 <xref:System.Reflection.MethodBase.Invoke%2A>」を参照してください。</span><span class="sxs-lookup"><span data-stu-id="11414-103">For more information, see <xref:System.Reflection.MethodBase.Invoke%2A>.</span></span>  
  
 <span data-ttu-id="11414-104">`TargetInvocationException` では、値 0x8013が4の HRESULT COR_E_TARGETINVOCATION を使用します。</span><span class="sxs-lookup"><span data-stu-id="11414-104">`TargetInvocationException` uses the HRESULT COR_E_TARGETINVOCATION which has the value 0x80131604.</span></span>  
  
 <span data-ttu-id="11414-105">作成した場合、`TargetInvocationException` には、リフレクションによって呼び出されたメソッドによってスローされた例外への参照が渡されます。</span><span class="sxs-lookup"><span data-stu-id="11414-105">When created, the `TargetInvocationException` is passed a reference to the exception thrown by the method invoked through reflection.</span></span> <span data-ttu-id="11414-106"><xref:System.Exception.InnerException%2A> プロパティは、基になる例外を保持します。</span><span class="sxs-lookup"><span data-stu-id="11414-106">The <xref:System.Exception.InnerException%2A> property holds the underlying exception.</span></span>  
  
 ]]></format>
    </remarks>
    <altmember cref="P:System.Exception.InnerException" />
    <altmember cref="T:System.Exception" />
    <related type="Article" href="~/docs/standard/exceptions/index.md"><span data-ttu-id="11414-107">.NET での例外の処理とスロー</span><span class="sxs-lookup"><span data-stu-id="11414-107">Handling and throwing exceptions in .NET</span></span></related>
  </Docs>
  <Members>
    <MemberGroup MemberName=".ctor">
      <AssemblyInfo>
        <AssemblyName>System.Reflection</AssemblyName>
        <AssemblyVersion>4.0.0.0</AssemblyVersion>
        <AssemblyVersion>4.0.10.0</AssemblyVersion>
        <AssemblyVersion>4.1.0.0</AssemblyVersion>
      </AssemblyInfo>
      <Docs>
        <summary><span data-ttu-id="11414-108"><see cref="T:System.Reflection.TargetInvocationException" /> クラスの新しいインスタンスを初期化します。</span><span class="sxs-lookup"><span data-stu-id="11414-108">Initializes a new instance of the <see cref="T:System.Reflection.TargetInvocationException" /> class.</span></span></summary>
      </Docs>
    </MemberGroup>
    <Member MemberName=".ctor">
      <MemberSignature Language="C#" Value="public TargetInvocationException (Exception inner);" />
      <MemberSignature Language="ILAsm" Value=".method public hidebysig specialname rtspecialname instance void .ctor(class System.Exception inner) cil managed" />
      <MemberSignature Language="DocId" Value="M:System.Reflection.TargetInvocationException.#ctor(System.Exception)" />
      <MemberSignature Language="VB.NET" Value="Public Sub New (inner As Exception)" />
      <MemberSignature Language="C++ CLI" Value="public:&#xA; TargetInvocationException(Exception ^ inner);" />
      <MemberSignature Language="F#" Value="new System.Reflection.TargetInvocationException : Exception -&gt; System.Reflection.TargetInvocationException" Usage="new System.Reflection.TargetInvocationException inner" />
      <MemberType>Constructor</MemberType>
      <AssemblyInfo>
        <AssemblyName>System.Reflection</AssemblyName>
        <AssemblyVersion>4.0.0.0</AssemblyVersion>
        <AssemblyVersion>4.0.10.0</AssemblyVersion>
        <AssemblyVersion>4.1.0.0</AssemblyVersion>
      </AssemblyInfo>
      <AssemblyInfo>
        <AssemblyName>mscorlib</AssemblyName>
        <AssemblyVersion>1.0.5000.0</AssemblyVersion>
        <AssemblyVersion>2.0.0.0</AssemblyVersion>
        <AssemblyVersion>2.0.5.0</AssemblyVersion>
        <AssemblyVersion>4.0.0.0</AssemblyVersion>
      </AssemblyInfo>
      <AssemblyInfo>
        <AssemblyName>netstandard</AssemblyName>
        <AssemblyVersion>2.0.0.0</AssemblyVersion>
        <AssemblyVersion>2.1.0.0</AssemblyVersion>
      </AssemblyInfo>
      <AssemblyInfo>
        <AssemblyName>System.Runtime</AssemblyName>
        <AssemblyVersion>4.2.0.0</AssemblyVersion>
        <AssemblyVersion>4.2.1.0</AssemblyVersion>
        <AssemblyVersion>4.2.2.0</AssemblyVersion>
      </AssemblyInfo>
      <Parameters>
        <Parameter Name="inner" Type="System.Exception" />
      </Parameters>
      <Docs>
        <param name="inner"><span data-ttu-id="11414-109">現在の例外の原因になった例外。</span><span class="sxs-lookup"><span data-stu-id="11414-109">The exception that is the cause of the current exception.</span></span> <span data-ttu-id="11414-110"><paramref name="inner" /> パラメーターが <see langword="null" /> でない場合は、内部例外を処理する <see langword="catch" /> ブロックで現在の例外が発生します。</span><span class="sxs-lookup"><span data-stu-id="11414-110">If the <paramref name="inner" /> parameter is not <see langword="null" />, the current exception is raised in a <see langword="catch" /> block that handles the inner exception.</span></span></param>
        <summary><span data-ttu-id="11414-111">この例外の原因である内部例外への参照を指定して、<see cref="T:System.Reflection.TargetInvocationException" /> クラスの新しいインスタンスを初期化します。</span><span class="sxs-lookup"><span data-stu-id="11414-111">Initializes a new instance of the <see cref="T:System.Reflection.TargetInvocationException" /> class with a reference to the inner exception that is the cause of this exception.</span></span></summary>
        <remarks>
          <format type="text/markdown"><![CDATA[  
  
## Remarks  
 <span data-ttu-id="11414-112">前の例外の直接の結果としてスローされる例外については、<xref:System.Exception.InnerException%2A> プロパティに、前の例外への参照を含める必要があります。</span><span class="sxs-lookup"><span data-stu-id="11414-112">An exception that is thrown as a direct result of a previous exception should include a reference to the previous exception in the <xref:System.Exception.InnerException%2A> property.</span></span> <span data-ttu-id="11414-113"><xref:System.Exception.InnerException%2A> プロパティは、コンストラクターに渡されたものと同じ値を返します。`null` プロパティによって内部例外値がコンストラクターに渡されなかった場合は、<xref:System.Exception.InnerException%2A> を返します。</span><span class="sxs-lookup"><span data-stu-id="11414-113">The <xref:System.Exception.InnerException%2A> property returns the same value that is passed into the constructor, or `null` if the <xref:System.Exception.InnerException%2A> property does not supply the inner exception value to the constructor.</span></span>  
  
 <span data-ttu-id="11414-114"><xref:System.Reflection.TargetInvocationException> インスタンスの初期プロパティ値を次の表に示します。</span><span class="sxs-lookup"><span data-stu-id="11414-114">The following table shows the initial property values for an instance of <xref:System.Reflection.TargetInvocationException>.</span></span>  
  
|<span data-ttu-id="11414-115">プロパティ</span><span class="sxs-lookup"><span data-stu-id="11414-115">Property</span></span>|<span data-ttu-id="11414-116">値</span><span class="sxs-lookup"><span data-stu-id="11414-116">Value</span></span>|  
|--------------|-----------|  
|<xref:System.Exception.InnerException%2A>|<span data-ttu-id="11414-117">内部例外の参照です。</span><span class="sxs-lookup"><span data-stu-id="11414-117">The inner exception reference.</span></span>|  
|<xref:System.Exception.Message%2A>|<span data-ttu-id="11414-118">エラー メッセージ文字列です。</span><span class="sxs-lookup"><span data-stu-id="11414-118">The error message string.</span></span>|  
  
 ]]></format>
        </remarks>
        <altmember cref="T:System.Exception" />
        <related type="Article" href="~/docs/standard/exceptions/index.md"><span data-ttu-id="11414-119">.NET での例外の処理とスロー</span><span class="sxs-lookup"><span data-stu-id="11414-119">Handling and throwing exceptions in .NET</span></span></related>
      </Docs>
    </Member>
    <Member MemberName=".ctor">
      <MemberSignature Language="C#" Value="public TargetInvocationException (string message, Exception inner);" />
      <MemberSignature Language="ILAsm" Value=".method public hidebysig specialname rtspecialname instance void .ctor(string message, class System.Exception inner) cil managed" />
      <MemberSignature Language="DocId" Value="M:System.Reflection.TargetInvocationException.#ctor(System.String,System.Exception)" />
      <MemberSignature Language="VB.NET" Value="Public Sub New (message As String, inner As Exception)" />
      <MemberSignature Language="C++ CLI" Value="public:&#xA; TargetInvocationException(System::String ^ message, Exception ^ inner);" />
      <MemberSignature Language="F#" Value="new System.Reflection.TargetInvocationException : string * Exception -&gt; System.Reflection.TargetInvocationException" Usage="new System.Reflection.TargetInvocationException (message, inner)" />
      <MemberType>Constructor</MemberType>
      <AssemblyInfo>
        <AssemblyName>System.Reflection</AssemblyName>
        <AssemblyVersion>4.0.0.0</AssemblyVersion>
        <AssemblyVersion>4.0.10.0</AssemblyVersion>
        <AssemblyVersion>4.1.0.0</AssemblyVersion>
      </AssemblyInfo>
      <AssemblyInfo>
        <AssemblyName>mscorlib</AssemblyName>
        <AssemblyVersion>1.0.5000.0</AssemblyVersion>
        <AssemblyVersion>2.0.0.0</AssemblyVersion>
        <AssemblyVersion>2.0.5.0</AssemblyVersion>
        <AssemblyVersion>4.0.0.0</AssemblyVersion>
      </AssemblyInfo>
      <AssemblyInfo>
        <AssemblyName>netstandard</AssemblyName>
        <AssemblyVersion>2.0.0.0</AssemblyVersion>
        <AssemblyVersion>2.1.0.0</AssemblyVersion>
      </AssemblyInfo>
      <AssemblyInfo>
        <AssemblyName>System.Runtime</AssemblyName>
        <AssemblyVersion>4.2.0.0</AssemblyVersion>
        <AssemblyVersion>4.2.1.0</AssemblyVersion>
        <AssemblyVersion>4.2.2.0</AssemblyVersion>
      </AssemblyInfo>
      <Parameters>
        <Parameter Name="message" Type="System.String" />
        <Parameter Name="inner" Type="System.Exception" />
      </Parameters>
      <Docs>
        <param name="message"><span data-ttu-id="11414-120">例外の原因を説明するエラー メッセージ。</span><span class="sxs-lookup"><span data-stu-id="11414-120">The error message that explains the reason for the exception.</span></span></param>
        <param name="inner"><span data-ttu-id="11414-121">現在の例外の原因になった例外。</span><span class="sxs-lookup"><span data-stu-id="11414-121">The exception that is the cause of the current exception.</span></span> <span data-ttu-id="11414-122"><paramref name="inner" /> パラメーターが <see langword="null" /> でない場合は、内部例外を処理する <see langword="catch" /> ブロックで現在の例外が発生します。</span><span class="sxs-lookup"><span data-stu-id="11414-122">If the <paramref name="inner" /> parameter is not <see langword="null" />, the current exception is raised in a <see langword="catch" /> block that handles the inner exception.</span></span></param>
        <summary><span data-ttu-id="11414-123">指定したエラー メッセージおよびこの例外の原因となった内部例外への参照を使用して、<see cref="T:System.Reflection.TargetInvocationException" /> クラスの新しいインスタンスを初期化します。</span><span class="sxs-lookup"><span data-stu-id="11414-123">Initializes a new instance of the <see cref="T:System.Reflection.TargetInvocationException" /> class with a specified error message and a reference to the inner exception that is the cause of this exception.</span></span></summary>
        <remarks>
          <format type="text/markdown"><![CDATA[  
  
## Remarks  
 <span data-ttu-id="11414-124">前の例外の直接の結果としてスローされる例外については、<xref:System.Exception.InnerException%2A> プロパティに、前の例外への参照を含める必要があります。</span><span class="sxs-lookup"><span data-stu-id="11414-124">An exception that is thrown as a direct result of a previous exception should include a reference to the previous exception in the <xref:System.Exception.InnerException%2A> property.</span></span> <span data-ttu-id="11414-125"><xref:System.Exception.InnerException%2A> プロパティは、コンストラクターに渡されたものと同じ値を返します。`null` プロパティによって内部例外値がコンストラクターに渡されなかった場合は、<xref:System.Exception.InnerException%2A> を返します。</span><span class="sxs-lookup"><span data-stu-id="11414-125">The <xref:System.Exception.InnerException%2A> property returns the same value that is passed into the constructor, or `null` if the <xref:System.Exception.InnerException%2A> property does not supply the inner exception value to the constructor.</span></span>  
  
 <span data-ttu-id="11414-126"><xref:System.Reflection.TargetInvocationException> インスタンスの初期プロパティ値を次の表に示します。</span><span class="sxs-lookup"><span data-stu-id="11414-126">The following table shows the initial property values for an instance of <xref:System.Reflection.TargetInvocationException>.</span></span>  
  
|<span data-ttu-id="11414-127">プロパティ</span><span class="sxs-lookup"><span data-stu-id="11414-127">Property</span></span>|<span data-ttu-id="11414-128">値</span><span class="sxs-lookup"><span data-stu-id="11414-128">Value</span></span>|  
|--------------|-----------|  
|<xref:System.Exception.InnerException%2A>|<span data-ttu-id="11414-129">内部例外の参照です。</span><span class="sxs-lookup"><span data-stu-id="11414-129">The inner exception reference.</span></span>|  
|<xref:System.Exception.Message%2A>|<span data-ttu-id="11414-130">エラー メッセージ文字列です。</span><span class="sxs-lookup"><span data-stu-id="11414-130">The error message string.</span></span>|  
  
 ]]></format>
        </remarks>
        <altmember cref="T:System.Exception" />
        <related type="Article" href="~/docs/standard/exceptions/index.md"><span data-ttu-id="11414-131">.NET での例外の処理とスロー</span><span class="sxs-lookup"><span data-stu-id="11414-131">Handling and throwing exceptions in .NET</span></span></related>
      </Docs>
    </Member>
  </Members>
</Type>
